Workbook

Sheet Dashboard
A1: Electricity Bill Anomaly Detector Dashboard
A3: MONTH | F3: DAY OF WEEK | K3: HOUSEHOLD (Top 10 by anomalies) | P3: ANOMALY STATUS
A4: 2011-12 | F4: Tuesday | K4: MAC004896 | P4: Normal
A6: AVG ENERGY (KWH/DAY) | F6: AVG ENERGY (KWH/DAY) | K6: ANOMALY COUNT | P6: RECORD COUNT
A7: =IF(A4="All Months",Data!$B$11,INDEX(Data!$J$3:$J$30,MATCH(A4,Data!$I$3:$I$30,0))) -> 12.149747 | F7: =IF(F4="All Days",Data!$B$11,INDEX(Data!$O$3:$O$9,MATCH(F4,Data!$N$3:$N$9,0))) -> 9.6058545 | K7: =IF(K4="All Households",Data!$B$7,INDEX(Data!$T$3:$T$12,MATCH(K4,Data!$R$3:$R$12,0))) -> 73 | P7: =IF(P4="All Status",Data!$B$4,INDEX(Data!$AI$3:$AI$5,MATCH(P4,Data!$AH$3:$AH$5,0))) -> 1001372
A8: ANOMALIES DETECTED | F8: ANOMALY RATE (%) | K8: ANOMALY RATE (%) | P8: SHARE OF ALL RECORDS (%)
A9: =IF(A4="All Months",Data!$B$7,INDEX(Data!$K$3:$K$30,MATCH(A4,Data!$I$3:$I$30,0))) -> 338 | F9: =IF(F4="All Days",Data!$B$10,INDEX(Data!$P$3:$P$9,MATCH(F4,Data!$N$3:$N$9,0))) -> 3.7451258 | K9: =IF(K4="All Households",Data!$B$10,INDEX(Data!$U$3:$U$12,MATCH(K4,Data!$R$3:$R$12,0))) -> 10.25 | P9: =IF(P4="All Status",100,INDEX(Data!$AI$3:$AI$5,MATCH(P4,Data!$AH$3:$AH$5,0))/Data!$B$4*100) -> 95.499278
A13: HOUSEHOLDS | F13: DAILY RECORDS | K13: TOTAL ANOMALIES | P13: ANOMALY RATE | U13: HIGH CONSUMPTION | Z13: LOW CONSUMPTION
A14: =Data!B3 -> 1636 | F14: =Data!B4 -> 1048565 | K14: =Data!B7 -> 47193 | P14: =Data!B10&"%" -> 4.5% | U14: =Data!B8 -> 34456 | Z14: =Data!B9 -> 12737
A19: WEEKLY ENERGY TREND (avg kWh/household/day) | R19: ANOMALY STATUS BREAKDOWN
A38: ANOMALY RATE BY DAY OF WEEK (%) | R38: TOP 10 HOUSEHOLDS BY ANOMALY COUNT
A57: TOP 15 MOST EXTREME ANOMALIES (ranked by anomaly score = |value − mean| / std)
A58: Household | F58: Date | K58: Energy (kWh) | P58: HH Mean | U58: HH Std | Y58: Status | AD58: Anomaly Score
A59: =Data!W3 -> MAC001372 | F59: =Data!X3 -> 2013-11-29 | K59: =Data!Y3 -> 22.988 | P59: =Data!Z3 -> 1.594 | U59: =Data!AA3 -> 1.122 | Y59: =Data!AB3 -> High Consumption | AD59: =Data!AC3 -> 19.07
A60: =Data!W4 -> MAC000937 | F60: =Data!X4 -> 2013-01-07 | K60: =Data!Y4 -> 16.391 | P60: =Data!Z4 -> 2.334 | U60: =Data!AA4 -> 0.867 | Y60: =Data!AB4 -> High Consumption | AD60: =Data!AC4 -> 16.22
A61: =Data!W5 -> MAC003099 | F61: =Data!X5 -> 2014-02-03 | K61: =Data!Y5 -> 16.998 | P61: =Data!Z5 -> 3.85 | U61: =Data!AA5 -> 0.834 | Y61: =Data!AB5 -> High Consumption | AD61: =Data!AC5 -> 15.77
A62: =Data!W6 -> MAC001106 | F62: =Data!X6 -> 2013-03-27 | K62: =Data!Y6 -> 22.99 | P62: =Data!Z6 -> 3.594 | U62: =Data!AA6 -> 1.24 | Y62: =Data!AB6 -> High Consumption | AD62: =Data!AC6 -> 15.64
A63: =Data!W7 -> MAC000958 | F63: =Data!X7 -> 2012-12-26 | K63: =Data!Y7 -> 103.194 | P63: =Data!Z7 -> 4.913 | U63: =Data!AA7 -> 6.625 | Y63: =Data!AB7 -> High Consumption | AD63: =Data!AC7 -> 14.84
A64: =Data!W8 -> MAC000962 | F64: =Data!X8 -> 2013-03-11 | K64: =Data!Y8 -> 24.885 | P64: =Data!Z8 -> 5.674 | U64: =Data!AA8 -> 1.31 | Y64: =Data!AB8 -> High Consumption | AD64: =Data!AC8 -> 14.66
A65: =Data!W9 -> MAC004803 | F65: =Data!X9 -> 2012-12-16 | K65: =Data!Y9 -> 53.384 | P65: =Data!Z9 -> 4.568 | U65: =Data!AA9 -> 3.349 | Y65: =Data!AB9 -> High Consumption | AD65: =Data!AC9 -> 14.58
A66: =Data!W10 -> MAC003616 | F66: =Data!X10 -> 2014-02-28 | K66: =Data!Y10 -> 0.032 | P66: =Data!Z10 -> 3.225 | U66: =Data!AA10 -> 0.221 | Y66: =Data!AB10 -> Low Consumption | AD66: =Data!AC10 -> 14.45
A67: =Data!W11 -> MAC001905 | F67: =Data!X11 -> 2012-11-18 | K67: =Data!Y11 -> 42.612 | P67: =Data!Z11 -> 5.265 | U67: =Data!AA11 -> 2.63 | Y67: =Data!AB11 -> High Consumption | AD67: =Data!AC11 -> 14.2
A68: =Data!W12 -> MAC000958 | F68: =Data!X12 -> 2012-12-27 | K68: =Data!Y12 -> 98.65 | P68: =Data!Z12 -> 4.913 | U68: =Data!AA12 -> 6.625 | Y68: =Data!AB12 -> High Consumption | AD68: =Data!AC12 -> 14.15
A69: =Data!W13 -> MAC000391 | F69: =Data!X13 -> 2013-01-15 | K69: =Data!Y13 -> 37.44 | P69: =Data!Z13 -> 7.421 | U69: =Data!AA13 -> 2.16 | Y69: =Data!AB13 -> High Consumption | AD69: =Data!AC13 -> 13.89
A70: =Data!W14 -> MAC001504 | F70: =Data!X14 -> 2012-10-26 | K70: =Data!Y14 -> 35.157 | P70: =Data!Z14 -> 3.632 | U70: =Data!AA14 -> 2.27 | Y70: =Data!AB14 -> High Consumption | AD70: =Data!AC14 -> 13.88
... A73: =Data!W17 -> MAC004805 | F73: =Data!X17 -> 2013-02-28 | K73: =Data!Y17 -> 43.696 | P73: =Data!Z17 -> 8.849 | U73: =Data!AA17 -> 2.62 | Y73: =Data!AB17 -> High Consumption | AD73: =Data!AC17 -> 13.3

Sheet Data
A1: KPIs | D1: Weekly | I1: Monthly | N1: DOW | R1: TopHouseholds | W1: TopRecords | AE1: Distribution | AH1: StatusCounts | AK1: MonthList | AL1: DayList | AM1: HouseholdList | AN1: StatusList
A2: Metric | B2: Value | D2: week | E2: avg_energy | F2: anomalies | G2: records | I2: month | J2: avg_energy | K2: anomalies | L2: records | N2: dow | O2: avg_energy | P2: anomaly_rate | R2: LCLid | S2: total_days | T2: anomaly_count | U2: anomaly_rate_pct | W2: LCLid | X2: day | Y2: energy_sum | Z2: mean | AA2: std | AB2: status | AC2: anomaly_score | AE2: range_kwh | AF2: count | AH2: status | AI2: count | AK2: All Months | AL2: All Days | AM2: All Households | AN2: All Status
A3: Total Households | B3: 1636 | D3: 2011-11-21 | E3: 10.977571 | F3: 6 | G3: 63 | I3: 2011-11 | J3: 10.310391 | K3: 10 | L3: 138 | N3: Monday | O3: 9.7307357 | P3: 3.7458695 | R3: MAC004292 | S3: 646 | T3: 95 | U3: 14.71 | W3: MAC001372 | X3: 2013-11-29 | Y3: 22.988 | Z3: 1.594 | AA3: 1.122 | AB3: High Consumption | AC3: 19.07 | AE3: 0-1 | AF3: 18917 | AH3: Normal | AI3: 1001372 | AK3: =I3 -> 2011-11 | AL3: =N3 -> Monday | AM3: =R3 -> MAC004292 | AN3: =AH3 -> Normal
A4: Total Daily Records | B4: 1048565 | D4: 2011-11-28 | E4: 11.10592 | F4: 14 | G4: 251 | I4: 2011-12 | J4: 12.149747 | K4: 338 | L4: 3042 | N4: Tuesday | O4: 9.6058545 | P4: 3.7451258 | R4: MAC000248 | S4: 819 | T4: 94 | U4: 11.48 | W4: MAC000937 | X4: 2013-01-07 | Y4: 16.391 | Z4: 2.334 | AA4: 0.867 | AB4: High Consumption | AC4: 16.22 | AE4: 1-2 | AF4: 35930 | AH4: High Consumption | AI4: 34456 | AK4: =I4 -> 2011-12 | AL4: =N4 -> Tuesday | AM4: =R4 -> MAC000248 | AN4: =AH4 -> High Consumption
A5: Date Range Start | B5: 2011-11-23 | D5: 2011-12-05 | E5: 12.118035 | F5: 35 | G5: 490 | I5: 2012-01 | J5: 12.592408 | K5: 372 | L5: 5174 | N5: Wednesday | O5: 9.6083017 | P5: 3.8940955 | R5: MAC004445 | S5: 674 | T5: 79 | U5: 11.72 | W5: MAC003099 | X5: 2014-02-03 | Y5: 16.998 | Z5: 3.85 | AA5: 0.834 | AB5: High Consumption | AC5: 15.77 | AE5: 2-3 | AF5: 66610 | AH5: Low Consumption | AI5: 12737 | AK5: =I5 -> 2012-01 | AL5: =N5 -> Wednesday | AM5: =R5 -> MAC004445 | AN5: =AH5 -> Low Consumption
A6: Date Range End | B6: 2014-02-28 | D6: 2011-12-12 | E6: 12.848858 | F6: 80 | G6: 669 | I6: 2012-02 | J6: 12.937144 | K6: 619 | L6: 6810 | N6: Thursday | O6: 9.6031629 | P6: 3.5146894 | R6: MAC005440 | S6: 684 | T6: 77 | U6: 11.26 | W6: MAC001106 | X6: 2013-03-27 | Y6: 22.99 | Z6: 3.594 | AA6: 1.24 | AB6: High Consumption | AC6: 15.64 | AE6: 3-5 | AF6: 184022 | AK6: =I6 -> 2012-02 | AL6: =N6 -> Thursday | AM6: =R6 -> MAC005440
A7: Total Anomalies | B7: 47193 | D7: 2011-12-19 | E7: 12.565296 | F7: 125 | G7: 858 | I7: 2012-03 | J7: 10.890557 | K7: 344 | L7: 9473 | N7: Friday | O7: 9.5291599 | P7: 4.6542359 | R7: MAC004896 | S7: 712 | T7: 73 | U7: 10.25 | W7: MAC000958 | X7: 2012-12-26 | Y7: 103.194 | Z7: 4.913 | AA7: 6.625 | AB7: High Consumption | AC7: 14.84 | AE7: 5-7 | AF7: 179840 | AK7: =I7 -> 2012-03 | AL7: =N7 -> Friday | AM7: =R7 -> MAC004896
A8: High-Consumption Anomalies | B8: 34456 | D8: 2011-12-26 | E8: 11.474835 | F8: 106 | G8: 999 | I8: 2012-04 | J8: 9.933773 | K8: 565 | L8: 14699 | N8: Saturday | O8: 9.8621807 | P8: 5.2018587 | R8: MAC000237 | S8: 804 | T8: 72 | U8: 8.96 | W8: MAC000962 | X8: 2013-03-11 | Y8: 24.885 | Z8: 5.674 | AA8: 1.31 | AB8: High Consumption | AC8: 14.66 | AE8: 7-10 | AF8: 205268 | AK8: =I8 -> 2012-04 | AL8: =N8 -> Saturday | AM8: =R8 -> MAC000237
A9: Low-Consumption Anomalies | B9: 12737 | D9: 2012-01-02 | E9: 12.752372 | F9: 88 | G9: 1067 | I9: 2012-05 | J9: 8.5869439 | K9: 883 | L9: 28311 | N9: Sunday | O9: 10.289413 | P9: 6.7626246 | R9: MAC002939 | S9: 606 | T9: 71 | U9: 11.72 | W9: MAC004803 | X9: 2012-12-16 | Y9: 53.384 | Z9: 4.568 | AA9: 3.349 | AB9: High Consumption | AC9: 14.58 | AE9: 10-15 | AF9: 188974 | AK9: =I9 -> 2012-05 | AL9: =N9 -> Sunday | AM9: =R9 -> MAC002939
A10: Anomaly Rate (%) | B10: 4.5 | D10: 2012-01-09 | E10: 12.508499 | F10: 69 | G10: 1094 | I10: 2012-06 | J10: 8.1159686 | K10: 1374 | L10: 37567 | R10: MAC000056 | S10: 813 | T10: 70 | U10: 8.61 | W10: MAC003616 | X10: 2014-02-28 | Y10: 0.032 | Z10: 3.225 | AA10: 0.221 | AB10: Low Consumption | AC10: 14.45 | AE10: 15-20 | AF10: 80664 | AK10: =I10 -> 2012-06 | AM10: =R10 -> MAC000056
A11: Avg Daily Energy (kWh) | B11: 9.746 | D11: 2012-01-16 | E11: 12.494697 | F11: 79 | G11: 1168 | I11: 2012-07 | J11: 8.0451005 | K11: 1002 | L11: 44526 | R11: MAC004576 | S11: 794 | T11: 69 | U11: 8.69 | W11: MAC001905 | X11: 2012-11-18 | Y11: 42.612 | Z11: 5.265 | AA11: 2.63 | AB11: High Consumption | AC11: 14.2 | AE11: 20-50 | AF11: 80993 | AK11: =I11 -> 2012-07 | AM11: =R11 -> MAC004576
A12: Total Energy Recorded (kWh) | B12: 10219682.0 | D12: 2012-01-23 | E12: 12.381342 | F12: 84 | G12: 1302 | I12: 2012-08 | J12: 7.852817 | K12: 1275 | L12: 45789 | R12: MAC004579 | S12: 794 | T12: 69 | U12: 8.69 | W12: MAC000958 | X12: 2012-12-27 | Y12: 98.65 | Z12: 4.913 | AA12: 6.625 | AB12: High Consumption | AC12: 14.15 | AE12: 50+ | AF12: 7347 | AK12: =I12 -> 2012-08 | AM12: =R12 -> MAC004579
D13: 2012-01-30 | E13: 13.916314 | F13: 193 | G13: 1470 | I13: 2012-09 | J13: 8.4649125 | K13: 1241 | L13: 44817 | W13: MAC000391 | X13: 2013-01-15 | Y13: 37.44 | Z13: 7.421 | AA13: 2.16 | AB13: High Consumption | AC13: 13.89 | AK13: =I13 -> 2012-09
D14: 2012-02-06 | E14: 14.246724 | F14: 215 | G14: 1588 | I14: 2012-10 | J14: 9.7527561 | K14: 1662 | L14: 48861 | W14: MAC001504 | X14: 2012-10-26 | Y14: 35.157 | Z14: 3.632 | AA14: 2.27 | AB14: High Consumption | AC14: 13.88 | AK14: =I14 -> 2012-10
D15: 2012-02-13 | E15: 12.627138 | F15: 120 | G15: 1656 | I15: 2012-11 | J15: 11.066042 | K15: 2092 | L15: 48847 | W15: MAC004087 | X15: 2013-04-02 | Y15: 94.341 | Z15: 16.704 | AA15: 5.698 | AB15: High Consumption | AC15: 13.62 | AK15: =I15 -> 2012-11
D16: 2012-02-20 | E16: 11.851299 | F16: 86 | G16: 1720 | I16: 2012-12 | J16: 11.903708 | K16: 4805 | L16: 50380 | W16: MAC003825 | X16: 2013-12-07 | Y16: 29.661 | Z16: 5.193 | AA16: 1.798 | AB16: High Consumption | AC16: 13.61 | AK16: =I16 -> 2012-12
D17: 2012-02-27 | E17: 11.736085 | F17: 102 | G17: 1830 | I17: 2013-01 | J17: 12.177858 | K17: 4132 | L17: 50186 | W17: MAC004805 | X17: 2013-02-28 | Y17: 43.696 | Z17: 8.849 | AA17: 2.62 | AB17: High Consumption | AC17: 13.3 | AK17: =I17 -> 2013-01
D18: 2012-03-05 | E18: 12.149049 | F18: 81 | G18: 1884 | I18: 2013-02 | J18: 12.028624 | K18: 3156 | L18: 45119 | AK18: =I18 -> 2013-02
D19: 2012-03-12 | E19: 11.142856 | F19: 59 | G19: 2102 | I19: 2013-03 | J19: 11.692601 | K19: 3362 | L19: 49392 | AK19: =I19 -> 2013-03
D20: 2012-03-19 | E20: 10.439787 | F20: 63 | G20: 2301 | I20: 2013-04 | J20: 9.7779914 | K20: 1480 | L20: 47544 | AK20: =I20 -> 2013-04
D21: 2012-03-26 | E21: 9.6664251 | F21: 93 | G21: 2484 | I21: 2013-05 | J21: 8.6365772 | K21: 965 | L21: 48901 | AK21: =I21 -> 2013-05
D22: 2012-04-02 | E22: 9.9255058 | F22: 151 | G22: 2768 | I22: 2013-06 | J22: 8.0421448 | K22: 902 | L22: 47098 | AK22: =I22 -> 2013-06
D23: 2012-04-09 | E23: 9.7768244 | F23: 128 | G23: 3076 | I23: 2013-07 | J23: 7.6939441 | K23: 927 | L23: 48433 | AK23: =I23 -> 2013-07
D24: 2012-04-16 | E24: 10.039869 | F24: 118 | G24: 3637 | I24: 2013-08 | J24: 7.5605442 | K24: 1361 | L24: 48158 | AK24: =I24 -> 2013-08
D25: 2012-04-23 | E25: 10.05744 | F25: 132 | G25: 4210 | I25: 2013-09 | J25: 8.3763288 | K25: 1189 | L25: 46359 | AK25: =I25 -> 2013-09
D26: 2012-04-30 | E26: 9.6023012 | F26: 164 | G26: 4911 | I26: 2013-10 | J26: 9.1118453 | K26: 1322 | L26: 47711 | AK26: =I26 -> 2013-10
D27: 2012-05-07 | E27: 9.1614576 | F27: 156 | G27: 5553 | I27: 2013-11 | J27: 10.639353 | K27: 2132 | L27: 45983 | AK27: =I27 -> 2013-11
D28: 2012-05-14 | E28: 8.7064534 | F28: 293 | G28: 6425 | I28: 2013-12 | J28: 11.118746 | K28: 3650 | L28: 46978 | AK28: =I28 -> 2013-12
D29: 2012-05-21 | E29: 7.9506404 | F29: 191 | G29: 7502 | I29: 2014-01 | J29: 11.090853 | K29: 2824 | L29: 46712 | AK29: =I29 -> 2014-01
D30: 2012-05-28 | E30: 7.9797226 | F30: 215 | G30: 8121 | I30: 2014-02 | J30: 10.349549 | K30: 3209 | L30: 41557 | AK30: =I30 -> 2014-02
D31: 2012-06-04 | E31: 8.4271702 | F31: 247 | G31: 8469
D32: 2012-06-11 | E32: 7.953036 | F32: 667 | G32: 8634
D33: 2012-06-18 | E33: 8.1111064 | F33: 202 | G33: 9083
D34: 2012-06-25 | E34: 7.9566911 | F34: 175 | G34: 9139
D35: 2012-07-02 | E35: 8.1693766 | F35: 237 | G35: 9522
D36: 2012-07-09 | E36: 8.1280715 | F36: 190 | G36: 10123
D37: 2012-07-16 | E37: 8.0084334 | F37: 215 | G37: 10305
D38: 2012-07-23 | E38: 7.8961918 | F38: 260 | G38: 10318
D39: 2012-07-30 | E39: 7.9135333 | F39: 290 | G39: 10329
D40: 2012-08-06 | E40: 7.8894906 | F40: 262 | G40: 10337
...
